package demo.operators;

import java.io.PrintWriter;

public class JavaException {
	public static void main(String args[]) {
		

		//outer try block
		//try {
			
			/*//inner try block1
			try {
				System.out.println("going to divided by zero");
				int b=39/0;
			}catch(ArithmeticException e) {
				System.out.println(e);
			}
			
			//inner try block2 
			try {
				int a[]=new int[5];
				a[5]=4;
			}
			//catch block of inner try block2
			catch(ArrayIndexOutOfBoundsException e) {
				System.out.println(e);
			}
			System.out.println("other statement");
		
			
			
	}
		//catch block of outer try block
		catch(Exception e) {
		System.out.println("handle the exception(outer catch)");
	}
		
		System.out.println("normal flow");*/
			//System.out.println("inside the try block");
		
		
			/*int data=25/0;
			System.out.println(data);
	}catch(ArithmeticException e) {
		System.out.println("handle  the exception");
		System.out.println(e);
	}
		finally {
			System.out.println("finally block always exceuted");
		}
		System.out.println("rest of the code");*/
		
	
		
	

	
	}	

}
